<mujoco model="linkage">
  <compiler angle="radian" autolimits="true"/>
  <statistic meansize="0.502494" extent="2.40957" center="0 0 -0.747711"/>
  <worldbody>
    <geom size="0.25 0.25 0.05" pos="0 0 0.1" type="box" contype="0" conaffinity="0" group="1" density="0" rgba="0.1 0.1 0.1 1"/>
    <body name="link B" pos="0 0 0.05">
      <inertial pos="0 0 -0.5" mass="0.5" diaginertia="0.5 0.5 0.5"/>
      <joint name="joint A" pos="0 0 0" axis="0 1 0"/>
      <geom size="0.05 0.5" pos="0 0 -0.5" type="cylinder" contype="0" conaffinity="0" group="1" density="0" rgba="0.3 0.3 0.3 1"/>
      <body name="link C" pos="0 0 -1">
        <inertial pos="0 0 -0.5" mass="0.5" diaginertia="0.5 0.5 0.5"/>
        <joint name="joint B" pos="0 0 0" axis="0 1 0" damping="0.002"/>
        <geom size="0.05 0.5" pos="0 0 -0.5" type="cylinder" contype="0" conaffinity="0" group="1" density="0"/>
      </body>
    </body>
  </worldbody>
</mujoco>
