<mujoco model="linkage">
	<compiler angle="radian" autolimits="true"/>
	<option timestep="0.001" integrator="RK4">
	<flag sensornoise="enable" energy="enable"/>
	</option>
	<worldbody>
	<!-- First link -->
    	<body name="link A" pos="0 0 2.5" >
		<inertial pos="0 0 0.25" mass="0.1" diaginertia="0.002 0.002 0.002"/>
    	<joint type="hinge" name="joint A" pos="0 0 0.5" axis="0 1 0"/>
    	<geom size="0.05 0.5" type="cylinder" rgba="0 0 0.9 1"/>
	<!-- Secind link (child) -->
    		<body name="link B" pos="0 0 0" >
			<inertial pos="0 0 0.25" mass="0.1" diaginertia="0.002 0.002 0.002"/>
        	<joint type="hinge" name="joint B" pos="0 0 -0.5" axis="0 1 0"/>
        	<geom size="0.05 0.5" type="cylinder" rgba="0 0.9 0 1"/>
      		</body>
    	</body>
  	</worldbody>
	<actuator> 
		<motor joint="joint A" gear = "1" ctrlrange="-100 100"/>
	</actuator>
	<actuator> 
		<motor joint="joint B" gear = "1" ctrlrange="-100 100"/>
	</actuator>
</mujoco>